<sdf version='1.6'>
  <world name='default'>
    <light name='sun' type='directional'>
      <cast_shadows>1</cast_shadows>
      <pose frame=''>0 0 10 0 -0 0</pose>
      <diffuse>0.8 0.8 0.8 1</diffuse>
      <specular>0.2 0.2 0.2 1</specular>
      <attenuation>
        <range>1000</range>
        <constant>0.9</constant>
        <linear>0.01</linear>
        <quadratic>0.001</quadratic>
      </attenuation>
      <direction>-0.5 0.1 -0.9</direction>
    </light>
    <model name='ground_plane'>
      <static>1</static>
      <link name='link'>
        <collision name='collision'>
          <geometry>
            <plane>
              <normal>0 0 1</normal>
              <size>100 100</size>
            </plane>
          </geometry>
          <surface>
            <contact>
              <collide_bitmask>65535</collide_bitmask>
              <ode/>
            </contact>
            <friction>
              <ode>
                <mu>100</mu>
                <mu2>50</mu2>
              </ode>
              <torsional>
                <ode/>
              </torsional>
            </friction>
            <bounce/>
          </surface>
          <max_contacts>10</max_contacts>
        </collision>
        <visual name='visual'>
          <cast_shadows>0</cast_shadows>
          <geometry>
            <plane>
              <normal>0 0 1</normal>
              <size>100 100</size>
            </plane>
          </geometry>
          <material>
            <script>
              <uri>file://media/materials/scripts/gazebo.material</uri>
              <name>Gazebo/Grey</name>
            </script>
          </material>
        </visual>
        <self_collide>0</self_collide>
        <enable_wind>0</enable_wind>
        <kinematic>0</kinematic>
      </link>
    </model>
    <gravity>0 0 -9.8</gravity>
    <magnetic_field>6e-06 2.3e-05 -4.2e-05</magnetic_field>
    <atmosphere type='adiabatic'/>
    <physics name='default_physics' default='0' type='ode'>
      <max_step_size>0.001</max_step_size>
      <real_time_factor>1</real_time_factor>
      <real_time_update_rate>1000</real_time_update_rate>
    </physics>
    <scene>
      <ambient>0.4 0.4 0.4 1</ambient>
      <background>0.7 0.7 0.7 1</background>
      <shadows>1</shadows>
    </scene>
    <audio>
      <device>default</device>
    </audio>
    <wind/>
    <spherical_coordinates>
      <surface_model>EARTH_WGS84</surface_model>
      <latitude_deg>0</latitude_deg>
      <longitude_deg>0</longitude_deg>
      <elevation>0</elevation>
      <heading_deg>0</heading_deg>
    </spherical_coordinates>
    <state world_name='default'>
      <sim_time>87 462000000</sim_time>
      <real_time>99 970991677</real_time>
      <wall_time>1620097475 525567924</wall_time>
      <iterations>87462</iterations>
      <model name='ground_plane'>
        <pose frame=''>0 0 0 0 -0 0</pose>
        <scale>1 1 1</scale>
        <link name='link'>
          <pose frame=''>0 0 0 0 -0 0</pose>
          <velocity>0 0 0 0 -0 0</velocity>
          <acceleration>0 0 0 0 -0 0</acceleration>
          <wrench>0 0 0 0 -0 0</wrench>
        </link>
      </model>
      <model name='husky_ur10'>
        <pose frame=''>1.49693 -4.43056 0.509637 0 -0 0</pose>
        <scale>1 1 1</scale>
        <model name='husky'>
          <pose frame=''>1.57041 -4.43853 0.392762 0 -0 0</pose>
          <scale>1 1 1</scale>
          <link name='back_left_wheel'>
            <pose frame=''>1.31441 -4.15305 0.427762 0 -0 0</pose>
            <velocity>0 0 0 0 -0 0</velocity>
            <acceleration>0 0 0 0 -0 0</acceleration>
            <wrench>0 0 0 0 -0 0</wrench>
          </link>
          <link name='back_right_wheel'>
            <pose frame=''>1.31441 -4.724 0.427762 0 -0 0</pose>
            <velocity>0 0 0 0 -0 0</velocity>
            <acceleration>0 0 0 0 -0 0</acceleration>
            <wrench>0 0 0 0 -0 0</wrench>
          </link>
          <link name='base_link'>
            <pose frame=''>1.57041 -4.43853 0.392762 0 -0 0</pose>
            <velocity>0 0 0 0 -0 0</velocity>
            <acceleration>0 0 0 0 -0 0</acceleration>
            <wrench>0 0 0 0 -0 0</wrench>
          </link>
          <link name='front_left_wheel'>
            <pose frame=''>1.82641 -4.15305 0.427762 0 -0 0</pose>
            <velocity>0 0 0 0 -0 0</velocity>
            <acceleration>0 0 0 0 -0 0</acceleration>
            <wrench>0 0 0 0 -0 0</wrench>
          </link>
          <link name='front_right_wheel'>
            <pose frame=''>1.82641 -4.724 0.427762 0 -0 0</pose>
            <velocity>0 0 0 0 -0 0</velocity>
            <acceleration>0 0 0 0 -0 0</acceleration>
            <wrench>0 0 0 0 -0 0</wrench>
          </link>
        </model>
        <model name='ur10'>
          <pose frame=''>1.42345 -4.4226 0.626512 0 -0 0</pose>
          <scale>1 1 1</scale>
          <link name='base'>
            <pose frame=''>1.42345 -4.4226 0.626512 0 -0 0</pose>
            <velocity>0 0 0 0 -0 0</velocity>
            <acceleration>0 0 0 0 -0 0</acceleration>
            <wrench>0 0 0 0 -0 0</wrench>
          </link>
          <link name='forearm'>
            <pose frame=''>2.03545 -4.37356 0.753812 3.14159 1.57079 3.14159</pose>
            <velocity>0 0 0 0 -0 0</velocity>
            <acceleration>0 0 0 0 -0 0</acceleration>
            <wrench>0 0 0 0 -0 0</wrench>
          </link>
          <link name='shoulder'>
            <pose frame=''>1.42345 -4.4226 0.753812 0 -0 0</pose>
            <velocity>0 0 0 0 -0 0</velocity>
            <acceleration>0 0 0 0 -0 0</acceleration>
            <wrench>0 0 0 0 -0 0</wrench>
          </link>
          <link name='upper_arm'>
            <pose frame=''>1.42345 -4.20166 0.753812 3.14159 1.57079 3.14159</pose>
            <velocity>0 0 0 0 -0 0</velocity>
            <acceleration>0 0 0 0 -0 0</acceleration>
            <wrench>0 0 0 0 -0 0</wrench>
          </link>
          <link name='wrist_1'>
            <pose frame=''>2.60775 -4.37356 0.753812 3.14159 -0 3.14159</pose>
            <velocity>0 0 0 0 -0 0</velocity>
            <acceleration>0 0 0 0 -0 0</acceleration>
            <wrench>0 0 0 0 -0 0</wrench>
          </link>
          <link name='wrist_2'>
            <pose frame=''>2.60775 -4.25866 0.753812 3.14159 -0 3.14159</pose>
            <velocity>0 0 0 0 -0 0</velocity>
            <acceleration>0 0 0 0 -0 0</acceleration>
            <wrench>0 0 0 0 -0 0</wrench>
          </link>
          <link name='wrist_3'>
            <pose frame=''>2.60775 -4.25866 0.638112 3.14159 -0 3.14159</pose>
            <velocity>0 0 0 0 -0 0</velocity>
            <acceleration>0 0 0 0 -0 0</acceleration>
            <wrench>0 0 0 0 -0 0</wrench>
          </link>
        </model>
      </model>
      <light name='sun'>
        <pose frame=''>0 0 10 0 -0 0</pose>
      </light>
    </state>
    <model name='husky_ur10'>
      <model name='husky'>
        <pose frame=''>0.073478 -0.007966 -0.116875 0 -0 0</pose>
        <link name='base_link'>
          <collision name='collision'>
            <pose frame=''>0 0 0.1 0 -0 0</pose>
            <geometry>
              <box>
                <size>1.0074 0.5709 0.2675</size>
              </box>
            </geometry>
            <max_contacts>10</max_contacts>
            <surface>
              <contact>
                <ode/>
              </contact>
              <bounce/>
              <friction>
                <torsional>
                  <ode/>
                </torsional>
                <ode/>
              </friction>
            </surface>
          </collision>
          <inertial>
            <mass>33.855</mass>
            <pose frame=''>-0.085613 -0.00084 0.238145 0 -0 0</pose>
            <inertia>
              <ixx>2.2343</ixx>
              <ixy>-0.023642</ixy>
              <ixz>0.275174</ixz>
              <iyy>3.42518</iyy>
              <iyz>0.00239624</iyz>
              <izz>2.1241</izz>
            </inertia>
          </inertial>
          <visual name='base'>
            <pose frame=''>0 0 0 0 -0 0</pose>
            <geometry>
              <mesh>
                <uri>model://husky/meshes/base_link.stl</uri>
              </mesh>
            </geometry>
            <material>
              <script>
                <name>Gazebo/FlatBlack</name>
                <uri>__default__</uri>
              </script>
            </material>
          </visual>
          <visual name='top_plate'>
            <pose frame=''>0 0 0 0 -0 0</pose>
            <geometry>
              <mesh>
                <uri>model://husky/meshes/top_plate.stl</uri>
              </mesh>
            </geometry>
            <material>
              <script>
                <name>Gazebo/Yellow</name>
                <uri>__default__</uri>
              </script>
            </material>
          </visual>
          <visual name='front_bumper'>
            <pose frame=''>0.47 0 0.091 0 -0 0</pose>
            <geometry>
              <mesh>
                <uri>model://husky/meshes/bumper.stl</uri>
              </mesh>
            </geometry>
            <material>
              <script>
                <name>Gazebo/FlatBlack</name>
                <uri>__default__</uri>
              </script>
            </material>
          </visual>
          <visual name='rear_bumper'>
            <pose frame=''>-0.47 0 0.091 0 -0 3.141</pose>
            <geometry>
              <mesh>
                <uri>model://husky/meshes/bumper.stl</uri>
              </mesh>
            </geometry>
            <material>
              <script>
                <name>Gazebo/FlatBlack</name>
                <uri>__default__</uri>
              </script>
            </material>
          </visual>
          <visual name='user_rail'>
            <pose frame=''>0.272 0 0.245 0 -0 0</pose>
            <geometry>
              <mesh>
                <uri>model://husky/meshes/user_rail.stl</uri>
              </mesh>
            </geometry>
            <material>
              <script>
                <name>Gazebo/Grey</name>
                <uri>__default__</uri>
              </script>
            </material>
          </visual>
          <self_collide>0</self_collide>
          <enable_wind>0</enable_wind>
          <kinematic>0</kinematic>
        </link>
        <link name='back_left_wheel'>
          <pose frame=''>-0.256 0.285475 0.035 0 -0 0</pose>
          <inertial>
            <mass>2.6357</mass>
            <pose frame=''>0 0 0 0 -0 0</pose>
            <inertia>
              <ixx>0.0246688</ixx>
              <ixy>0</ixy>
              <ixz>0</ixz>
              <iyy>0.0246688</iyy>
              <iyz>0</iyz>
              <izz>0.0441058</izz>
            </inertia>
          </inertial>
          <collision name='back_left_wheel_collision'>
            <pose frame=''>0 0 0 -1.5707 0 0</pose>
            <geometry>
              <cylinder>
                <radius>0.17775</radius>
                <length>0.1143</length>
              </cylinder>
            </geometry>
            <surface>
              <friction>
                <ode>
                  <mu>100000</mu>
                  <mu2>100000</mu2>
                  <slip1>0</slip1>
                  <slip2>0</slip2>
                </ode>
                <torsional>
                  <ode/>
                </torsional>
              </friction>
              <contact>
                <ode/>
              </contact>
              <bounce/>
            </surface>
            <max_contacts>10</max_contacts>
          </collision>
          <visual name='back_left_wheel'>
            <pose frame=''>0 0 0 -3.14159 0 0</pose>
            <geometry>
              <mesh>
                <uri>model://husky/meshes/wheel.stl</uri>
              </mesh>
            </geometry>
            <material>
              <script>
                <name>Gazebo/Grey</name>
                <uri>__default__</uri>
              </script>
            </material>
          </visual>
          <self_collide>0</self_collide>
          <enable_wind>0</enable_wind>
          <kinematic>0</kinematic>
        </link>
        <joint name='back_left_joint' type='revolute'>
          <parent>base_link</parent>
          <child>back_left_wheel</child>
          <axis>
            <xyz>0 1 0</xyz>
            <use_parent_model_frame>1</use_parent_model_frame>
            <limit>
              <lower>-1e+16</lower>
              <upper>1e+16</upper>
            </limit>
            <dynamics>
              <spring_reference>0</spring_reference>
              <spring_stiffness>0</spring_stiffness>
            </dynamics>
          </axis>
          <physics>
            <ode>
              <limit>
                <cfm>0</cfm>
                <erp>0.9</erp>
              </limit>
            </ode>
          </physics>
        </joint>
        <link name='back_right_wheel'>
          <pose frame=''>-0.256 -0.285475 0.035 0 -0 0</pose>
          <inertial>
            <mass>2.6357</mass>
            <pose frame=''>0 0 0 0 -0 0</pose>
            <inertia>
              <ixx>0.0246688</ixx>
              <ixy>0</ixy>
              <ixz>0</ixz>
              <iyy>0.0246688</iyy>
              <iyz>0</iyz>
              <izz>0.0441058</izz>
            </inertia>
          </inertial>
          <collision name='back_right_wheel_collision'>
            <pose frame=''>0 0 0 -1.5707 0 0</pose>
            <geometry>
              <cylinder>
                <radius>0.17775</radius>
                <length>0.1143</length>
              </cylinder>
            </geometry>
            <surface>
              <friction>
                <ode>
                  <mu>100000</mu>
                  <mu2>100000</mu2>
                  <slip1>0</slip1>
                  <slip2>0</slip2>
                </ode>
                <torsional>
                  <ode/>
                </torsional>
              </friction>
              <contact>
                <ode/>
              </contact>
              <bounce/>
            </surface>
            <max_contacts>10</max_contacts>
          </collision>
          <visual name='back_right_wheel'>
            <pose frame=''>0 0 0 -3.14159 0 0</pose>
            <geometry>
              <mesh>
                <uri>model://husky/meshes/wheel.stl</uri>
              </mesh>
            </geometry>
            <material>
              <script>
                <name>Gazebo/Grey</name>
                <uri>__default__</uri>
              </script>
            </material>
          </visual>
          <self_collide>0</self_collide>
          <enable_wind>0</enable_wind>
          <kinematic>0</kinematic>
        </link>
        <joint name='back_right_joint' type='revolute'>
          <parent>base_link</parent>
          <child>back_right_wheel</child>
          <axis>
            <xyz>0 1 0</xyz>
            <use_parent_model_frame>1</use_parent_model_frame>
            <limit>
              <lower>-1e+16</lower>
              <upper>1e+16</upper>
            </limit>
            <dynamics>
              <spring_reference>0</spring_reference>
              <spring_stiffness>0</spring_stiffness>
            </dynamics>
          </axis>
          <physics>
            <ode>
              <limit>
                <cfm>0</cfm>
                <erp>0.9</erp>
              </limit>
            </ode>
          </physics>
        </joint>
        <link name='front_left_wheel'>
          <pose frame=''>0.256 0.285475 0.035 0 -0 0</pose>
          <inertial>
            <mass>2.6357</mass>
            <pose frame=''>0 0 0 0 -0 0</pose>
            <inertia>
              <ixx>0.0246688</ixx>
              <ixy>0</ixy>
              <ixz>0</ixz>
              <iyy>0.0246688</iyy>
              <iyz>0</iyz>
              <izz>0.0441058</izz>
            </inertia>
          </inertial>
          <collision name='front_left_wheel_collision'>
            <pose frame=''>0 0 0 -1.5707 0 0</pose>
            <geometry>
              <cylinder>
                <radius>0.17775</radius>
                <length>0.1143</length>
              </cylinder>
            </geometry>
            <surface>
              <friction>
                <ode>
                  <mu>100000</mu>
                  <mu2>100000</mu2>
                  <slip1>0</slip1>
                  <slip2>0</slip2>
                </ode>
                <torsional>
                  <ode/>
                </torsional>
              </friction>
              <contact>
                <ode/>
              </contact>
              <bounce/>
            </surface>
            <max_contacts>10</max_contacts>
          </collision>
          <visual name='front_left_wheel'>
            <pose frame=''>0 0 0 -3.14159 0 0</pose>
            <geometry>
              <mesh>
                <uri>model://husky/meshes/wheel.stl</uri>
              </mesh>
            </geometry>
            <material>
              <script>
                <name>Gazebo/Grey</name>
                <uri>__default__</uri>
              </script>
            </material>
          </visual>
          <self_collide>0</self_collide>
          <enable_wind>0</enable_wind>
          <kinematic>0</kinematic>
        </link>
        <joint name='front_left_joint' type='revolute'>
          <parent>base_link</parent>
          <child>front_left_wheel</child>
          <axis>
            <xyz>0 1 0</xyz>
            <use_parent_model_frame>1</use_parent_model_frame>
            <limit>
              <lower>-1e+16</lower>
              <upper>1e+16</upper>
            </limit>
            <dynamics>
              <spring_reference>0</spring_reference>
              <spring_stiffness>0</spring_stiffness>
            </dynamics>
          </axis>
          <physics>
            <ode>
              <limit>
                <cfm>0</cfm>
                <erp>0.9</erp>
              </limit>
            </ode>
          </physics>
        </joint>
        <link name='front_right_wheel'>
          <pose frame=''>0.256 -0.285475 0.035 0 -0 0</pose>
          <inertial>
            <mass>2.6357</mass>
            <pose frame=''>0 0 0 0 -0 0</pose>
            <inertia>
              <ixx>0.0246688</ixx>
              <ixy>0</ixy>
              <ixz>0</ixz>
              <iyy>0.0246688</iyy>
              <iyz>0</iyz>
              <izz>0.0441058</izz>
            </inertia>
          </inertial>
          <collision name='front_right_wheel_collision'>
            <pose frame=''>0 0 0 -1.5707 0 0</pose>
            <geometry>
              <cylinder>
                <radius>0.17775</radius>
                <length>0.1143</length>
              </cylinder>
            </geometry>
            <surface>
              <friction>
                <ode>
                  <mu>100000</mu>
                  <mu2>100000</mu2>
                  <slip1>0</slip1>
                  <slip2>0</slip2>
                </ode>
                <torsional>
                  <ode/>
                </torsional>
              </friction>
              <contact>
                <ode/>
              </contact>
              <bounce/>
            </surface>
            <max_contacts>10</max_contacts>
          </collision>
          <visual name='front_right_wheel'>
            <pose frame=''>0 0 0 -3.14159 0 0</pose>
            <geometry>
              <mesh>
                <uri>model://husky/meshes/wheel.stl</uri>
              </mesh>
            </geometry>
            <material>
              <script>
                <name>Gazebo/Grey</name>
                <uri>__default__</uri>
              </script>
            </material>
          </visual>
          <self_collide>0</self_collide>
          <enable_wind>0</enable_wind>
          <kinematic>0</kinematic>
        </link>
        <joint name='front_right_joint' type='revolute'>
          <parent>base_link</parent>
          <child>front_right_wheel</child>
          <axis>
            <xyz>0 1 0</xyz>
            <use_parent_model_frame>1</use_parent_model_frame>
            <limit>
              <lower>-1e+16</lower>
              <upper>1e+16</upper>
            </limit>
            <dynamics>
              <spring_reference>0</spring_reference>
              <spring_stiffness>0</spring_stiffness>
            </dynamics>
          </axis>
          <physics>
            <ode>
              <limit>
                <cfm>0</cfm>
                <erp>0.9</erp>
              </limit>
            </ode>
          </physics>
        </joint>
        <plugin name='husky_diff_controller' filename='libhusky_gazebo_plugins.so'>
          <alwaysOn>1</alwaysOn>
          <updateRate>100.0</updateRate>
          <backLeftJoint>back_left_joint</backLeftJoint>
          <backRightJoint>back_right_joint</backRightJoint>
          <frontLeftJoint>front_left_joint</frontLeftJoint>
          <frontRightJoint>front_right_joint</frontRightJoint>
          <wheelSeparation>0.5709</wheelSeparation>
          <wheelDiameter>0.3555</wheelDiameter>
          <torque>35</torque>
        </plugin>
      </model>
      <model name='ur10'>
        <link name='base'>
          <inertial>
            <mass>4</mass>
            <inertia>
              <ixx>0.00610633</ixx>
              <ixy>0</ixy>
              <ixz>0</ixz>
              <iyy>0.00610633</iyy>
              <iyz>0</iyz>
              <izz>0.01125</izz>
            </inertia>
          </inertial>
          <collision name='collision'>
            <pose frame=''>0 0 0.019 0 -0 0</pose>
            <geometry>
              <cylinder>
                <radius>0.075</radius>
                <length>0.038</length>
              </cylinder>
            </geometry>
            <max_contacts>10</max_contacts>
            <surface>
              <contact>
                <ode/>
              </contact>
              <bounce/>
              <friction>
                <torsional>
                  <ode/>
                </torsional>
                <ode/>
              </friction>
            </surface>
          </collision>
          <visual name='visual'>
            <geometry>
              <mesh>
                <uri>model://ur10/meshes/base.dae</uri>
              </mesh>
            </geometry>
          </visual>
          <self_collide>0</self_collide>
          <enable_wind>0</enable_wind>
          <kinematic>0</kinematic>
        </link>
        <link name='shoulder'>
          <pose frame=''>0 0 0.1273 0 -0 0</pose>
          <inertial>
            <mass>7.778</mass>
            <inertia>
              <ixx>0.0314743</ixx>
              <ixy>0</ixy>
              <ixz>0</ixz>
              <iyy>0.0314743</iyy>
              <iyz>0</iyz>
              <izz>0.0218756</izz>
            </inertia>
          </inertial>
          <collision name='collision'>
            <geometry>
              <cylinder>
                <radius>0.075</radius>
                <length>0.177</length>
              </cylinder>
            </geometry>
            <max_contacts>10</max_contacts>
            <surface>
              <contact>
                <ode/>
              </contact>
              <bounce/>
              <friction>
                <torsional>
                  <ode/>
                </torsional>
                <ode/>
              </friction>
            </surface>
          </collision>
          <visual name='visual'>
            <geometry>
              <mesh>
                <uri>model://ur10/meshes/shoulder.dae</uri>
              </mesh>
            </geometry>
          </visual>
          <self_collide>0</self_collide>
          <enable_wind>0</enable_wind>
          <kinematic>0</kinematic>
        </link>
        <link name='upper_arm'>
          <pose frame=''>0 0.220941 0.1273 3.14159 1.57079 3.14159</pose>
          <inertial>
            <pose frame=''>0 0 0.306 0 -0 0</pose>
            <mass>12.93</mass>
            <inertia>
              <ixx>0.421754</ixx>
              <ixy>0</ixy>
              <ixz>0</ixz>
              <iyy>0.421754</iyy>
              <iyz>0</iyz>
              <izz>0.0363656</izz>
            </inertia>
          </inertial>
          <collision name='collision1'>
            <pose frame=''>0 -0.045 0 1.5707 -0 0</pose>
            <geometry>
              <cylinder>
                <radius>0.075</radius>
                <length>0.177</length>
              </cylinder>
            </geometry>
            <max_contacts>10</max_contacts>
            <surface>
              <contact>
                <ode/>
              </contact>
              <bounce/>
              <friction>
                <torsional>
                  <ode/>
                </torsional>
                <ode/>
              </friction>
            </surface>
          </collision>
          <collision name='collision2'>
            <pose frame=''>0 -0.0436 0.32 0 -0 1.5707</pose>
            <geometry>
              <cylinder>
                <radius>0.058</radius>
                <length>0.461</length>
              </cylinder>
            </geometry>
            <max_contacts>10</max_contacts>
            <surface>
              <contact>
                <ode/>
              </contact>
              <bounce/>
              <friction>
                <torsional>
                  <ode/>
                </torsional>
                <ode/>
              </friction>
            </surface>
          </collision>
          <collision name='collision3'>
            <pose frame=''>0 -0.04 0.613 1.5707 -0 0</pose>
            <geometry>
              <cylinder>
                <radius>0.058</radius>
                <length>0.129</length>
              </cylinder>
            </geometry>
            <max_contacts>10</max_contacts>
            <surface>
              <contact>
                <ode/>
              </contact>
              <bounce/>
              <friction>
                <torsional>
                  <ode/>
                </torsional>
                <ode/>
              </friction>
            </surface>
          </collision>
          <visual name='visual'>
            <geometry>
              <mesh>
                <uri>model://ur10/meshes/upperarm.dae</uri>
              </mesh>
            </geometry>
          </visual>
          <self_collide>0</self_collide>
          <enable_wind>0</enable_wind>
          <kinematic>0</kinematic>
        </link>
        <link name='forearm'>
          <pose frame=''>0.612 0.049041 0.1273 3.14159 1.57079 3.14159</pose>
          <inertial>
            <pose frame=''>0 0 0.28615 0 -0 0</pose>
            <mass>3.87</mass>
            <inertia>
              <ixx>0.11107</ixx>
              <ixy>0</ixy>
              <ixz>0</ixz>
              <iyy>0.11107</iyy>
              <iyz>0</iyz>
              <izz>0.0108844</izz>
            </inertia>
          </inertial>
          <collision name='collision1'>
            <pose frame=''>0 0 0.001 1.5707 -0 0</pose>
            <geometry>
              <cylinder>
                <radius>0.058</radius>
                <length>0.136</length>
              </cylinder>
            </geometry>
            <max_contacts>10</max_contacts>
            <surface>
              <contact>
                <ode/>
              </contact>
              <bounce/>
              <friction>
                <torsional>
                  <ode/>
                </torsional>
                <ode/>
              </friction>
            </surface>
          </collision>
          <collision name='collision2'>
            <pose frame=''>0 0 0.305 0 -0 1.5707</pose>
            <geometry>
              <cylinder>
                <radius>0.045</radius>
                <length>0.447</length>
              </cylinder>
            </geometry>
            <max_contacts>10</max_contacts>
            <surface>
              <contact>
                <ode/>
              </contact>
              <bounce/>
              <friction>
                <torsional>
                  <ode/>
                </torsional>
                <ode/>
              </friction>
            </surface>
          </collision>
          <collision name='collision3'>
            <pose frame=''>0 0.001 0.5735 1.5707 -0 0</pose>
            <geometry>
              <cylinder>
                <radius>0.045</radius>
                <length>0.119</length>
              </cylinder>
            </geometry>
            <max_contacts>10</max_contacts>
            <surface>
              <contact>
                <ode/>
              </contact>
              <bounce/>
              <friction>
                <torsional>
                  <ode/>
                </torsional>
                <ode/>
              </friction>
            </surface>
          </collision>
          <visual name='visua'>
            <geometry>
              <mesh>
                <uri>model://ur10/meshes/forearm.dae</uri>
              </mesh>
            </geometry>
          </visual>
          <self_collide>0</self_collide>
          <enable_wind>0</enable_wind>
          <kinematic>0</kinematic>
        </link>
        <link name='wrist_1'>
          <pose frame=''>1.1843 0.049041 0.1273 3.14159 -0 3.14159</pose>
          <inertial>
            <mass>1.96</mass>
            <inertia>
              <ixx>0.00510825</ixx>
              <ixy>0</ixy>
              <ixz>0</ixz>
              <iyy>0.00510825</iyy>
              <iyz>0</iyz>
              <izz>0.0055125</izz>
            </inertia>
          </inertial>
          <collision name='collision'>
            <pose frame=''>0 0.115 0.0025 0 -0 0</pose>
            <geometry>
              <cylinder>
                <radius>0.0455</radius>
                <length>0.119</length>
              </cylinder>
            </geometry>
            <max_contacts>10</max_contacts>
            <surface>
              <contact>
                <ode/>
              </contact>
              <bounce/>
              <friction>
                <torsional>
                  <ode/>
                </torsional>
                <ode/>
              </friction>
            </surface>
          </collision>
          <visual name='visual'>
            <geometry>
              <mesh>
                <uri>model://ur10/meshes/wrist1.dae</uri>
              </mesh>
            </geometry>
          </visual>
          <self_collide>0</self_collide>
          <enable_wind>0</enable_wind>
          <kinematic>0</kinematic>
        </link>
        <link name='wrist_2'>
          <pose frame=''>1.1843 0.163941 0.1273 3.14159 -0 3.14159</pose>
          <inertial>
            <mass>1.96</mass>
            <inertia>
              <ixx>0.00510825</ixx>
              <ixy>0</ixy>
              <ixz>0</ixz>
              <iyy>0.00510825</iyy>
              <iyz>0</iyz>
              <izz>0.0055125</izz>
            </inertia>
          </inertial>
          <collision name='collision'>
            <pose frame=''>0 0.002 0.11659 1.5707 -0 0</pose>
            <geometry>
              <cylinder>
                <radius>0.0455</radius>
                <length>0.119</length>
              </cylinder>
            </geometry>
            <max_contacts>10</max_contacts>
            <surface>
              <contact>
                <ode/>
              </contact>
              <bounce/>
              <friction>
                <torsional>
                  <ode/>
                </torsional>
                <ode/>
              </friction>
            </surface>
          </collision>
          <visual name='visual'>
            <geometry>
              <mesh>
                <uri>model://ur10/meshes/wrist2.dae</uri>
              </mesh>
            </geometry>
          </visual>
          <self_collide>0</self_collide>
          <enable_wind>0</enable_wind>
          <kinematic>0</kinematic>
        </link>
        <link name='wrist_3'>
          <pose frame=''>1.1843 0.163941 0.0116 3.14159 -0 3.14159</pose>
          <inertial>
            <mass>0.202</mass>
            <inertia>
              <ixx>0.000526462</ixx>
              <ixy>0</ixy>
              <ixz>0</ixz>
              <iyy>0.000526462</iyy>
              <iyz>0</iyz>
              <izz>0.000568125</izz>
            </inertia>
          </inertial>
          <collision name='collision'>
            <pose frame=''>0 0.0765 0 1.5707 -0 0</pose>
            <geometry>
              <cylinder>
                <radius>0.045</radius>
                <length>0.031</length>
              </cylinder>
            </geometry>
            <max_contacts>10</max_contacts>
            <surface>
              <contact>
                <ode/>
              </contact>
              <bounce/>
              <friction>
                <torsional>
                  <ode/>
                </torsional>
                <ode/>
              </friction>
            </surface>
          </collision>
          <visual name='visual'>
            <geometry>
              <mesh>
                <uri>model://ur10/meshes/wrist3.dae</uri>
              </mesh>
            </geometry>
          </visual>
          <self_collide>0</self_collide>
          <enable_wind>0</enable_wind>
          <kinematic>0</kinematic>
        </link>
        <joint name='shoulder_pan' type='revolute'>
          <child>shoulder</child>
          <parent>base</parent>
          <axis>
            <xyz>0 0 1</xyz>
            <limit>
              <lower>-6.28319</lower>
              <upper>6.28319</upper>
              <effort>330</effort>
              <velocity>2.16</velocity>
            </limit>
            <use_parent_model_frame>1</use_parent_model_frame>
            <dynamics>
              <spring_reference>0</spring_reference>
              <spring_stiffness>0</spring_stiffness>
            </dynamics>
          </axis>
        </joint>
        <joint name='shoulder_lift' type='revolute'>
          <child>upper_arm</child>
          <parent>shoulder</parent>
          <axis>
            <xyz>0 1 0</xyz>
            <limit>
              <lower>-6.28319</lower>
              <upper>6.28319</upper>
              <effort>330</effort>
              <velocity>2.16</velocity>
            </limit>
            <use_parent_model_frame>1</use_parent_model_frame>
            <dynamics>
              <spring_reference>0</spring_reference>
              <spring_stiffness>0</spring_stiffness>
            </dynamics>
          </axis>
        </joint>
        <joint name='elbow' type='revolute'>
          <child>forearm</child>
          <parent>upper_arm</parent>
          <axis>
            <xyz>0 1 0</xyz>
            <limit>
              <lower>-6.28319</lower>
              <upper>6.28319</upper>
              <effort>150</effort>
              <velocity>3.15</velocity>
            </limit>
            <use_parent_model_frame>1</use_parent_model_frame>
            <dynamics>
              <spring_reference>0</spring_reference>
              <spring_stiffness>0</spring_stiffness>
            </dynamics>
          </axis>
        </joint>
        <joint name='wrist_1' type='revolute'>
          <child>wrist_1</child>
          <parent>forearm</parent>
          <axis>
            <xyz>0 1 0</xyz>
            <limit>
              <lower>-6.28319</lower>
              <upper>6.28319</upper>
              <effort>54</effort>
              <velocity>3.2</velocity>
            </limit>
            <use_parent_model_frame>1</use_parent_model_frame>
            <dynamics>
              <spring_reference>0</spring_reference>
              <spring_stiffness>0</spring_stiffness>
            </dynamics>
          </axis>
        </joint>
        <joint name='wrist_2' type='revolute'>
          <child>wrist_2</child>
          <parent>wrist_1</parent>
          <axis>
            <xyz>0 0 -1</xyz>
            <limit>
              <lower>-6.28319</lower>
              <upper>6.28319</upper>
              <effort>54</effort>
              <velocity>3.2</velocity>
            </limit>
            <use_parent_model_frame>1</use_parent_model_frame>
            <dynamics>
              <spring_reference>0</spring_reference>
              <spring_stiffness>0</spring_stiffness>
            </dynamics>
          </axis>
        </joint>
        <joint name='wrist_3' type='revolute'>
          <child>wrist_3</child>
          <parent>wrist_2</parent>
          <axis>
            <xyz>0 1 0</xyz>
            <limit>
              <lower>-6.28319</lower>
              <upper>6.28319</upper>
              <effort>54</effort>
              <velocity>3.2</velocity>
            </limit>
            <use_parent_model_frame>1</use_parent_model_frame>
            <dynamics>
              <spring_reference>0</spring_reference>
              <spring_stiffness>0</spring_stiffness>
            </dynamics>
          </axis>
        </joint>
        <pose frame=''>-0.073478 0.007961 0.116875 0 -0 0</pose>
      </model>
      <joint name='base_link_JOINT_0' type='revolute'>
        <parent>husky::base_link</parent>
        <child>ur10::base</child>
        <pose frame=''>0 0 0 0 -0 0</pose>
        <axis>
          <xyz>0 0 1</xyz>
          <use_parent_model_frame>0</use_parent_model_frame>
          <limit>
            <lower>-1.79769e+308</lower>
            <upper>1.79769e+308</upper>
            <effort>-1</effort>
            <velocity>-1</velocity>
          </limit>
          <dynamics>
            <spring_reference>0</spring_reference>
            <spring_stiffness>0</spring_stiffness>
            <damping>0</damping>
          </dynamics>
        </axis>
        <physics>
          <ode>
            <limit>
              <cfm>0</cfm>
              <erp>0.2</erp>
            </limit>
            <suspension>
              <cfm>0</cfm>
              <erp>0.2</erp>
            </suspension>
          </ode>
        </physics>
      </joint>
      <static>0</static>
      <allow_auto_disable>1</allow_auto_disable>
      <pose frame=''>1.49693 -4.43056 0 0 -0 0</pose>
    </model>
    <gui fullscreen='0'>
      <camera name='user_camera'>
        <pose frame=''>-0.979893 -3.90358 2.56679 0 0.687643 -0.155804</pose>
        <view_controller>orbit</view_controller>
        <projection_type>perspective</projection_type>
      </camera>
    </gui>
  </world>
</sdf>
